[2022-12-01 19:41:43,288: INFO/MainProcess] Connected to redis://redis:6379/0
[2022-12-01 19:41:43,313: INFO/MainProcess] mingle: searching for neighbors
[2022-12-01 19:41:44,361: INFO/MainProcess] mingle: all alone
[2022-12-01 19:41:44,462: WARNING/MainProcess] /usr/local/lib/python3.9/site-packages/celery/fixups/django.py:203: UserWarning: Using settings.DEBUG leads to a memory
            leak, never use this setting in production environments!
  warnings.warn('''Using settings.DEBUG leads to a memory

[2022-12-01 19:41:44,467: INFO/MainProcess] celery@34c82f12f97e ready.
[2022-12-01 19:41:51,915: INFO/MainProcess] Events of group {task} enabled by remote.
[2022-12-01 20:32:46,405: ERROR/MainProcess] consumer: Cannot connect to redis://redis:6379/0: Error -2 connecting to redis:6379. Name does not resolve..
Trying again in 2.00 seconds... (1/100)

[2022-12-01 20:32:48,455: ERROR/MainProcess] consumer: Cannot connect to redis://redis:6379/0: Error -2 connecting to redis:6379. Name does not resolve..
Trying again in 4.00 seconds... (2/100)

[2022-12-01 20:32:52,501: ERROR/MainProcess] consumer: Cannot connect to redis://redis:6379/0: Error -2 connecting to redis:6379. Name does not resolve..
Trying again in 6.00 seconds... (3/100)

[2022-12-01 20:32:58,570: ERROR/MainProcess] consumer: Cannot connect to redis://redis:6379/0: Error -2 connecting to redis:6379. Name does not resolve..
Trying again in 8.00 seconds... (4/100)

[2022-12-01 20:33:06,661: ERROR/MainProcess] consumer: Cannot connect to redis://redis:6379/0: Error -2 connecting to redis:6379. Name does not resolve..
Trying again in 10.00 seconds... (5/100)

[2022-12-01 20:33:16,727: ERROR/MainProcess] consumer: Cannot connect to redis://redis:6379/0: Error -2 connecting to redis:6379. Name does not resolve..
Trying again in 12.00 seconds... (6/100)

[2022-12-01 20:33:28,792: ERROR/MainProcess] consumer: Cannot connect to redis://redis:6379/0: Error -2 connecting to redis:6379. Name does not resolve..
Trying again in 14.00 seconds... (7/100)

[2022-12-01 20:33:42,868: ERROR/MainProcess] consumer: Cannot connect to redis://redis:6379/0: Error -2 connecting to redis:6379. Name does not resolve..
Trying again in 16.00 seconds... (8/100)

[2022-12-01 20:33:58,941: ERROR/MainProcess] consumer: Cannot connect to redis://redis:6379/0: Error -2 connecting to redis:6379. Name does not resolve..
Trying again in 18.00 seconds... (9/100)

[2022-12-01 20:34:17,014: ERROR/MainProcess] consumer: Cannot connect to redis://redis:6379/0: Error -2 connecting to redis:6379. Name does not resolve..
Trying again in 20.00 seconds... (10/100)

[2022-12-01 20:34:37,133: ERROR/MainProcess] consumer: Cannot connect to redis://redis:6379/0: Error -2 connecting to redis:6379. Name does not resolve..
Trying again in 22.00 seconds... (11/100)

[2022-12-01 20:34:59,608: ERROR/MainProcess] consumer: Cannot connect to redis://redis:6379/0: Error -2 connecting to redis:6379. Name does not resolve..
Trying again in 24.00 seconds... (12/100)

[2022-12-01 20:35:24,250: ERROR/MainProcess] consumer: Cannot connect to redis://redis:6379/0: Error -2 connecting to redis:6379. Name does not resolve..
Trying again in 26.00 seconds... (13/100)

[2022-12-01 20:35:51,784: ERROR/MainProcess] consumer: Cannot connect to redis://redis:6379/0: Error -2 connecting to redis:6379. Name does not resolve..
Trying again in 28.00 seconds... (14/100)

[2022-12-01 20:36:23,661: ERROR/MainProcess] consumer: Cannot connect to redis://redis:6379/0: Error -2 connecting to redis:6379. Name does not resolve..
Trying again in 30.00 seconds... (15/100)

[2022-12-01 20:36:55,662: ERROR/MainProcess] consumer: Cannot connect to redis://redis:6379/0: Error -2 connecting to redis:6379. Name does not resolve..
Trying again in 32.00 seconds... (16/100)

[2022-12-01 20:37:28,195: ERROR/MainProcess] consumer: Cannot connect to redis://redis:6379/0: Error -2 connecting to redis:6379. Name does not resolve..
Trying again in 32.00 seconds... (16/100)

[2022-12-01 20:38:02,144: ERROR/MainProcess] consumer: Cannot connect to redis://redis:6379/0: Error -2 connecting to redis:6379. Name does not resolve..
Trying again in 32.00 seconds... (16/100)

[2022-12-01 20:38:34,375: ERROR/MainProcess] consumer: Cannot connect to redis://redis:6379/0: Error -2 connecting to redis:6379. Name does not resolve..
Trying again in 32.00 seconds... (16/100)

[2022-12-01 20:39:12,560: ERROR/MainProcess] consumer: Cannot connect to redis://redis:6379/0: Error -2 connecting to redis:6379. Name does not resolve..
Trying again in 32.00 seconds... (16/100)

[2022-12-01 20:39:49,768: ERROR/MainProcess] consumer: Cannot connect to redis://redis:6379/0: Error -2 connecting to redis:6379. Name does not resolve..
Trying again in 32.00 seconds... (16/100)

[2022-12-01 20:40:22,003: ERROR/MainProcess] consumer: Cannot connect to redis://redis:6379/0: Error -2 connecting to redis:6379. Name does not resolve..
Trying again in 32.00 seconds... (16/100)

[2022-12-01 20:40:54,109: ERROR/MainProcess] consumer: Cannot connect to redis://redis:6379/0: Error -2 connecting to redis:6379. Name does not resolve..
Trying again in 32.00 seconds... (16/100)

[2022-12-01 20:41:26,353: ERROR/MainProcess] consumer: Cannot connect to redis://redis:6379/0: Error -2 connecting to redis:6379. Name does not resolve..
Trying again in 32.00 seconds... (16/100)

[2022-12-01 20:41:58,547: ERROR/MainProcess] consumer: Cannot connect to redis://redis:6379/0: Error -2 connecting to redis:6379. Name does not resolve..
Trying again in 32.00 seconds... (16/100)

[2022-12-01 20:42:30,627: ERROR/MainProcess] consumer: Cannot connect to redis://redis:6379/0: Error -2 connecting to redis:6379. Name does not resolve..
Trying again in 32.00 seconds... (16/100)

[2022-12-01 20:43:02,731: ERROR/MainProcess] consumer: Cannot connect to redis://redis:6379/0: Error -2 connecting to redis:6379. Name does not resolve..
Trying again in 32.00 seconds... (16/100)

[2022-12-01 20:43:34,846: ERROR/MainProcess] consumer: Cannot connect to redis://redis:6379/0: Error -2 connecting to redis:6379. Name does not resolve..
Trying again in 32.00 seconds... (16/100)

[2022-12-01 20:44:06,958: ERROR/MainProcess] consumer: Cannot connect to redis://redis:6379/0: Error -2 connecting to redis:6379. Name does not resolve..
Trying again in 32.00 seconds... (16/100)

[2022-12-01 20:44:39,261: ERROR/MainProcess] consumer: Cannot connect to redis://redis:6379/0: Error -2 connecting to redis:6379. Name does not resolve..
Trying again in 32.00 seconds... (16/100)

[2022-12-01 20:45:12,035: ERROR/MainProcess] consumer: Cannot connect to redis://redis:6379/0: Error -2 connecting to redis:6379. Name does not resolve..
Trying again in 32.00 seconds... (16/100)

[2022-12-01 20:45:44,148: ERROR/MainProcess] consumer: Cannot connect to redis://redis:6379/0: Error -2 connecting to redis:6379. Name does not resolve..
Trying again in 32.00 seconds... (16/100)

[2022-12-01 20:46:16,316: ERROR/MainProcess] consumer: Cannot connect to redis://redis:6379/0: Error -2 connecting to redis:6379. Name does not resolve..
Trying again in 32.00 seconds... (16/100)

[2022-12-01 20:46:48,432: ERROR/MainProcess] consumer: Cannot connect to redis://redis:6379/0: Error -2 connecting to redis:6379. Name does not resolve..
Trying again in 32.00 seconds... (16/100)

[2022-12-01 20:47:20,837: ERROR/MainProcess] consumer: Cannot connect to redis://redis:6379/0: Error -2 connecting to redis:6379. Name does not resolve..
Trying again in 32.00 seconds... (16/100)

[2022-12-01 20:47:53,211: ERROR/MainProcess] consumer: Cannot connect to redis://redis:6379/0: Error -2 connecting to redis:6379. Name does not resolve..
Trying again in 32.00 seconds... (16/100)

[2022-12-01 20:48:25,344: ERROR/MainProcess] consumer: Cannot connect to redis://redis:6379/0: Error -2 connecting to redis:6379. Name does not resolve..
Trying again in 32.00 seconds... (16/100)

[2022-12-01 20:48:57,443: ERROR/MainProcess] consumer: Cannot connect to redis://redis:6379/0: Error -2 connecting to redis:6379. Name does not resolve..
Trying again in 32.00 seconds... (16/100)

[2022-12-01 20:49:29,592: ERROR/MainProcess] consumer: Cannot connect to redis://redis:6379/0: Error -2 connecting to redis:6379. Name does not resolve..
Trying again in 32.00 seconds... (16/100)

[2022-12-01 20:50:01,672: ERROR/MainProcess] consumer: Cannot connect to redis://redis:6379/0: Error -2 connecting to redis:6379. Name does not resolve..
Trying again in 32.00 seconds... (16/100)

[2022-12-01 20:50:33,780: ERROR/MainProcess] consumer: Cannot connect to redis://redis:6379/0: Error -2 connecting to redis:6379. Name does not resolve..
Trying again in 32.00 seconds... (16/100)

[2022-12-01 20:51:05,937: ERROR/MainProcess] consumer: Cannot connect to redis://redis:6379/0: Error -2 connecting to redis:6379. Name does not resolve..
Trying again in 32.00 seconds... (16/100)

[2022-12-01 20:51:38,401: ERROR/MainProcess] consumer: Cannot connect to redis://redis:6379/0: Error -2 connecting to redis:6379. Name does not resolve..
Trying again in 32.00 seconds... (16/100)

[2022-12-01 20:52:10,497: ERROR/MainProcess] consumer: Cannot connect to redis://redis:6379/0: Error -2 connecting to redis:6379. Name does not resolve..
Trying again in 32.00 seconds... (16/100)

[2022-12-01 20:52:42,565: ERROR/MainProcess] consumer: Cannot connect to redis://redis:6379/0: Error -2 connecting to redis:6379. Name does not resolve..
Trying again in 32.00 seconds... (16/100)

[2022-12-01 20:53:14,678: ERROR/MainProcess] consumer: Cannot connect to redis://redis:6379/0: Error -2 connecting to redis:6379. Name does not resolve..
Trying again in 32.00 seconds... (16/100)

[2022-12-01 20:53:46,904: ERROR/MainProcess] consumer: Cannot connect to redis://redis:6379/0: Error -2 connecting to redis:6379. Name does not resolve..
Trying again in 32.00 seconds... (16/100)

[2022-12-01 20:54:19,020: ERROR/MainProcess] consumer: Cannot connect to redis://redis:6379/0: Error -2 connecting to redis:6379. Name does not resolve..
Trying again in 32.00 seconds... (16/100)

[2022-12-01 20:54:51,134: ERROR/MainProcess] consumer: Cannot connect to redis://redis:6379/0: Error -2 connecting to redis:6379. Name does not resolve..
Trying again in 32.00 seconds... (16/100)

[2022-12-01 20:55:23,953: ERROR/MainProcess] consumer: Cannot connect to redis://redis:6379/0: Error -2 connecting to redis:6379. Name does not resolve..
Trying again in 32.00 seconds... (16/100)

[2022-12-01 20:55:57,196: ERROR/MainProcess] consumer: Cannot connect to redis://redis:6379/0: Error -2 connecting to redis:6379. Name does not resolve..
Trying again in 32.00 seconds... (16/100)

[2022-12-01 20:56:29,946: ERROR/MainProcess] consumer: Cannot connect to redis://redis:6379/0: Error -2 connecting to redis:6379. Name does not resolve..
Trying again in 32.00 seconds... (16/100)

[2022-12-01 20:57:02,207: ERROR/MainProcess] consumer: Cannot connect to redis://redis:6379/0: Error -2 connecting to redis:6379. Name does not resolve..
Trying again in 32.00 seconds... (16/100)

[2022-12-01 20:57:34,310: ERROR/MainProcess] consumer: Cannot connect to redis://redis:6379/0: Error -2 connecting to redis:6379. Name does not resolve..
Trying again in 32.00 seconds... (16/100)

[2022-12-01 20:58:07,026: ERROR/MainProcess] consumer: Cannot connect to redis://redis:6379/0: Error -2 connecting to redis:6379. Name does not resolve..
Trying again in 32.00 seconds... (16/100)

[2022-12-01 20:58:39,233: ERROR/MainProcess] consumer: Cannot connect to redis://redis:6379/0: Error -2 connecting to redis:6379. Name does not resolve..
Trying again in 32.00 seconds... (16/100)

[2022-12-01 20:59:11,387: ERROR/MainProcess] consumer: Cannot connect to redis://redis:6379/0: Error -2 connecting to redis:6379. Name does not resolve..
Trying again in 32.00 seconds... (16/100)

[2022-12-01 20:59:43,637: ERROR/MainProcess] consumer: Cannot connect to redis://redis:6379/0: Error -2 connecting to redis:6379. Name does not resolve..
Trying again in 32.00 seconds... (16/100)

[2022-12-01 21:00:19,601: ERROR/MainProcess] consumer: Cannot connect to redis://redis:6379/0: Error -2 connecting to redis:6379. Name does not resolve..
Trying again in 32.00 seconds... (16/100)

[2022-12-01 21:00:51,752: ERROR/MainProcess] consumer: Cannot connect to redis://redis:6379/0: Error -2 connecting to redis:6379. Name does not resolve..
Trying again in 32.00 seconds... (16/100)

[2022-12-01 21:01:24,245: ERROR/MainProcess] consumer: Cannot connect to redis://redis:6379/0: Error -2 connecting to redis:6379. Name does not resolve..
Trying again in 32.00 seconds... (16/100)

[2022-12-01 21:01:56,417: ERROR/MainProcess] consumer: Cannot connect to redis://redis:6379/0: Error -2 connecting to redis:6379. Name does not resolve..
Trying again in 32.00 seconds... (16/100)

[2022-12-01 21:02:28,482: ERROR/MainProcess] consumer: Cannot connect to redis://redis:6379/0: Error -2 connecting to redis:6379. Name does not resolve..
Trying again in 32.00 seconds... (16/100)

[2022-12-01 21:03:00,541: ERROR/MainProcess] consumer: Cannot connect to redis://redis:6379/0: Error -2 connecting to redis:6379. Name does not resolve..
Trying again in 32.00 seconds... (16/100)

[2022-12-01 21:03:32,626: ERROR/MainProcess] consumer: Cannot connect to redis://redis:6379/0: Error -2 connecting to redis:6379. Name does not resolve..
Trying again in 32.00 seconds... (16/100)

[2022-12-01 21:04:04,709: ERROR/MainProcess] consumer: Cannot connect to redis://redis:6379/0: Error -2 connecting to redis:6379. Name does not resolve..
Trying again in 32.00 seconds... (16/100)

[2022-12-01 21:04:36,824: ERROR/MainProcess] consumer: Cannot connect to redis://redis:6379/0: Error -2 connecting to redis:6379. Name does not resolve..
Trying again in 32.00 seconds... (16/100)

[2022-12-01 21:05:08,970: ERROR/MainProcess] consumer: Cannot connect to redis://redis:6379/0: Error -2 connecting to redis:6379. Name does not resolve..
Trying again in 32.00 seconds... (16/100)

[2022-12-01 21:05:41,126: ERROR/MainProcess] consumer: Cannot connect to redis://redis:6379/0: Error -2 connecting to redis:6379. Name does not resolve..
Trying again in 32.00 seconds... (16/100)

[2022-12-01 21:06:13,214: ERROR/MainProcess] consumer: Cannot connect to redis://redis:6379/0: Error -2 connecting to redis:6379. Name does not resolve..
Trying again in 32.00 seconds... (16/100)

[2022-12-01 21:06:45,301: ERROR/MainProcess] consumer: Cannot connect to redis://redis:6379/0: Error -2 connecting to redis:6379. Name does not resolve..
Trying again in 32.00 seconds... (16/100)

[2022-12-01 21:07:17,416: ERROR/MainProcess] consumer: Cannot connect to redis://redis:6379/0: Error -2 connecting to redis:6379. Name does not resolve..
Trying again in 32.00 seconds... (16/100)

[2022-12-01 21:07:49,593: ERROR/MainProcess] consumer: Cannot connect to redis://redis:6379/0: Error -2 connecting to redis:6379. Name does not resolve..
Trying again in 32.00 seconds... (16/100)

[2022-12-01 21:08:21,813: ERROR/MainProcess] consumer: Cannot connect to redis://redis:6379/0: Error -2 connecting to redis:6379. Name does not resolve..
Trying again in 32.00 seconds... (16/100)

[2022-12-01 21:08:53,890: ERROR/MainProcess] consumer: Cannot connect to redis://redis:6379/0: Error -2 connecting to redis:6379. Name does not resolve..
Trying again in 32.00 seconds... (16/100)

[2022-12-01 21:09:26,156: ERROR/MainProcess] consumer: Cannot connect to redis://redis:6379/0: Error -2 connecting to redis:6379. Name does not resolve..
Trying again in 32.00 seconds... (16/100)

[2022-12-01 21:09:58,320: ERROR/MainProcess] consumer: Cannot connect to redis://redis:6379/0: Error -2 connecting to redis:6379. Name does not resolve..
Trying again in 32.00 seconds... (16/100)

[2022-12-01 21:10:30,484: ERROR/MainProcess] consumer: Cannot connect to redis://redis:6379/0: Error -2 connecting to redis:6379. Name does not resolve..
Trying again in 32.00 seconds... (16/100)

[2022-12-01 21:11:02,614: ERROR/MainProcess] consumer: Cannot connect to redis://redis:6379/0: Error -2 connecting to redis:6379. Name does not resolve..
Trying again in 32.00 seconds... (16/100)

[2022-12-01 21:11:34,700: ERROR/MainProcess] consumer: Cannot connect to redis://redis:6379/0: Error -2 connecting to redis:6379. Name does not resolve..
Trying again in 32.00 seconds... (16/100)

[2022-12-01 21:12:06,784: ERROR/MainProcess] consumer: Cannot connect to redis://redis:6379/0: Error -2 connecting to redis:6379. Name does not resolve..
Trying again in 32.00 seconds... (16/100)

[2022-12-01 21:12:39,015: ERROR/MainProcess] consumer: Cannot connect to redis://redis:6379/0: Error -2 connecting to redis:6379. Name does not resolve..
Trying again in 32.00 seconds... (16/100)

[2022-12-01 21:13:11,215: ERROR/MainProcess] consumer: Cannot connect to redis://redis:6379/0: Error -2 connecting to redis:6379. Name does not resolve..
Trying again in 32.00 seconds... (16/100)

[2022-12-01 21:13:43,337: ERROR/MainProcess] consumer: Cannot connect to redis://redis:6379/0: Error -2 connecting to redis:6379. Name does not resolve..
Trying again in 32.00 seconds... (16/100)

[2022-12-01 21:14:15,521: ERROR/MainProcess] consumer: Cannot connect to redis://redis:6379/0: Error -2 connecting to redis:6379. Name does not resolve..
Trying again in 32.00 seconds... (16/100)

[2022-12-01 21:14:47,669: ERROR/MainProcess] consumer: Cannot connect to redis://redis:6379/0: Error -2 connecting to redis:6379. Name does not resolve..
Trying again in 32.00 seconds... (16/100)

[2022-12-01 21:15:19,785: ERROR/MainProcess] consumer: Cannot connect to redis://redis:6379/0: Error -2 connecting to redis:6379. Name does not resolve..
Trying again in 32.00 seconds... (16/100)

[2022-12-01 21:15:51,885: ERROR/MainProcess] consumer: Cannot connect to redis://redis:6379/0: Error -2 connecting to redis:6379. Name does not resolve..
Trying again in 32.00 seconds... (16/100)

[2022-12-01 21:16:24,080: ERROR/MainProcess] consumer: Cannot connect to redis://redis:6379/0: Error -2 connecting to redis:6379. Name does not resolve..
Trying again in 32.00 seconds... (16/100)

[2022-12-01 21:16:56,427: ERROR/MainProcess] consumer: Cannot connect to redis://redis:6379/0: Error -2 connecting to redis:6379. Name does not resolve..
Trying again in 32.00 seconds... (16/100)

[2022-12-01 21:17:28,544: ERROR/MainProcess] consumer: Cannot connect to redis://redis:6379/0: Error -2 connecting to redis:6379. Name does not resolve..
Trying again in 32.00 seconds... (16/100)

[2022-12-01 21:18:00,645: ERROR/MainProcess] consumer: Cannot connect to redis://redis:6379/0: Error -2 connecting to redis:6379. Name does not resolve..
Trying again in 32.00 seconds... (16/100)

[2022-12-01 21:18:32,764: ERROR/MainProcess] consumer: Cannot connect to redis://redis:6379/0: Error -2 connecting to redis:6379. Name does not resolve..
Trying again in 32.00 seconds... (16/100)

[2022-12-01 21:19:04,855: ERROR/MainProcess] consumer: Cannot connect to redis://redis:6379/0: Error -2 connecting to redis:6379. Name does not resolve..
Trying again in 32.00 seconds... (16/100)

[2022-12-01 21:20:09,104: ERROR/MainProcess] consumer: Cannot connect to redis://redis:6379/0: Error -2 connecting to redis:6379. Name does not resolve..
Trying again in 32.00 seconds... (16/100)

[2022-12-01 21:20:41,221: ERROR/MainProcess] consumer: Cannot connect to redis://redis:6379/0: Error -2 connecting to redis:6379. Name does not resolve..
Trying again in 32.00 seconds... (16/100)

[2022-12-01 21:21:13,310: ERROR/MainProcess] consumer: Cannot connect to redis://redis:6379/0: Error -2 connecting to redis:6379. Name does not resolve..
Trying again in 32.00 seconds... (16/100)

[2022-12-01 21:21:45,437: ERROR/MainProcess] consumer: Cannot connect to redis://redis:6379/0: Error -2 connecting to redis:6379. Name does not resolve..
Trying again in 32.00 seconds... (16/100)

[2022-12-01 21:22:17,533: ERROR/MainProcess] consumer: Cannot connect to redis://redis:6379/0: Error -2 connecting to redis:6379. Name does not resolve..
Trying again in 32.00 seconds... (16/100)

[2022-12-01 21:22:49,791: CRITICAL/MainProcess] Unrecoverable error: OperationalError('Error -2 connecting to redis:6379. Name does not resolve.')
Traceback (most recent call last):
  File "/usr/local/lib/python3.9/site-packages/kombu/transport/virtual/base.py", line 925, in create_channel
    return self._avail_channels.pop()
IndexError: pop from empty list

During handling of the above exception, another exception occurred:

Traceback (most recent call last):
  File "/usr/local/lib/python3.9/site-packages/redis/connection.py", line 611, in connect
    sock = self.retry.call_with_retry(
  File "/usr/local/lib/python3.9/site-packages/redis/retry.py", line 46, in call_with_retry
    return do()
  File "/usr/local/lib/python3.9/site-packages/redis/connection.py", line 612, in <lambda>
    lambda: self._connect(), lambda error: self.disconnect(error)
  File "/usr/local/lib/python3.9/site-packages/redis/connection.py", line 645, in _connect
    for res in socket.getaddrinfo(
  File "/usr/local/lib/python3.9/socket.py", line 953, in getaddrinfo
    for res in _socket.getaddrinfo(host, port, family, type, proto, flags):
socket.gaierror: [Errno -2] Name does not resolve

During handling of the above exception, another exception occurred:

Traceback (most recent call last):
  File "/usr/local/lib/python3.9/site-packages/kombu/connection.py", line 446, in _reraise_as_library_errors
    yield
  File "/usr/local/lib/python3.9/site-packages/kombu/connection.py", line 433, in _ensure_connection
    return retry_over_time(
  File "/usr/local/lib/python3.9/site-packages/kombu/utils/functional.py", line 312, in retry_over_time
    return fun(*args, **kwargs)
  File "/usr/local/lib/python3.9/site-packages/kombu/connection.py", line 877, in _connection_factory
    self._connection = self._establish_connection()
  File "/usr/local/lib/python3.9/site-packages/kombu/connection.py", line 812, in _establish_connection
    conn = self.transport.establish_connection()
  File "/usr/local/lib/python3.9/site-packages/kombu/transport/virtual/base.py", line 949, in establish_connection
    self._avail_channels.append(self.create_channel(self))
  File "/usr/local/lib/python3.9/site-packages/kombu/transport/virtual/base.py", line 927, in create_channel
    channel = self.Channel(connection)
  File "/usr/local/lib/python3.9/site-packages/kombu/transport/redis.py", line 737, in __init__
    self.client.ping()
  File "/usr/local/lib/python3.9/site-packages/redis/commands/core.py", line 1132, in ping
    return self.execute_command("PING", **kwargs)
  File "/usr/local/lib/python3.9/site-packages/redis/client.py", line 1235, in execute_command
    conn = self.connection or pool.get_connection(command_name, **options)
  File "/usr/local/lib/python3.9/site-packages/redis/connection.py", line 1387, in get_connection
    connection.connect()
  File "/usr/local/lib/python3.9/site-packages/redis/connection.py", line 617, in connect
    raise ConnectionError(self._error_message(e))
redis.exceptions.ConnectionError: Error -2 connecting to redis:6379. Name does not resolve.

The above exception was the direct cause of the following exception:

Traceback (most recent call last):
  File "/usr/local/lib/python3.9/site-packages/celery/worker/worker.py", line 203, in start
    self.blueprint.start(self)
  File "/usr/local/lib/python3.9/site-packages/celery/bootsteps.py", line 116, in start
    step.start(parent)
  File "/usr/local/lib/python3.9/site-packages/celery/bootsteps.py", line 365, in start
    return self.obj.start()
  File "/usr/local/lib/python3.9/site-packages/celery/worker/consumer/consumer.py", line 332, in start
    blueprint.start(self)
  File "/usr/local/lib/python3.9/site-packages/celery/bootsteps.py", line 116, in start
    step.start(parent)
  File "/usr/local/lib/python3.9/site-packages/celery/worker/consumer/connection.py", line 21, in start
    c.connection = c.connect()
  File "/usr/local/lib/python3.9/site-packages/celery/worker/consumer/consumer.py", line 428, in connect
    conn = self.connection_for_read(heartbeat=self.amqheartbeat)
  File "/usr/local/lib/python3.9/site-packages/celery/worker/consumer/consumer.py", line 434, in connection_for_read
    return self.ensure_connected(
  File "/usr/local/lib/python3.9/site-packages/celery/worker/consumer/consumer.py", line 460, in ensure_connected
    conn = conn.ensure_connection(
  File "/usr/local/lib/python3.9/site-packages/kombu/connection.py", line 381, in ensure_connection
    self._ensure_connection(*args, **kwargs)
  File "/usr/local/lib/python3.9/site-packages/kombu/connection.py", line 433, in _ensure_connection
    return retry_over_time(
  File "/usr/local/lib/python3.9/contextlib.py", line 135, in __exit__
    self.gen.throw(type, value, traceback)
  File "/usr/local/lib/python3.9/site-packages/kombu/connection.py", line 450, in _reraise_as_library_errors
    raise ConnectionError(str(exc)) from exc
kombu.exceptions.OperationalError: Error -2 connecting to redis:6379. Name does not resolve.
[2022-12-01 21:23:04,860: ERROR/MainProcess] consumer: Cannot connect to redis://redis:6379/0: Error -2 connecting to redis:6379. Name does not resolve..
Trying again in 2.00 seconds... (1/100)

[2022-12-01 21:23:06,891: ERROR/MainProcess] consumer: Cannot connect to redis://redis:6379/0: Error -2 connecting to redis:6379. Name does not resolve..
Trying again in 4.00 seconds... (2/100)

[2022-12-01 21:23:10,939: ERROR/MainProcess] consumer: Cannot connect to redis://redis:6379/0: Error -2 connecting to redis:6379. Name does not resolve..
Trying again in 6.00 seconds... (3/100)

[2022-12-01 21:23:17,009: ERROR/MainProcess] consumer: Cannot connect to redis://redis:6379/0: Error -2 connecting to redis:6379. Name does not resolve..
Trying again in 8.00 seconds... (4/100)

[2022-12-01 21:23:25,044: ERROR/MainProcess] consumer: Cannot connect to redis://redis:6379/0: Error -2 connecting to redis:6379. Name does not resolve..
Trying again in 10.00 seconds... (5/100)

[2022-12-01 21:23:35,077: ERROR/MainProcess] consumer: Cannot connect to redis://redis:6379/0: Error -2 connecting to redis:6379. Name does not resolve..
Trying again in 12.00 seconds... (6/100)

[2022-12-01 21:23:47,162: ERROR/MainProcess] consumer: Cannot connect to redis://redis:6379/0: Error -2 connecting to redis:6379. Name does not resolve..
Trying again in 14.00 seconds... (7/100)

[2022-12-01 21:24:01,254: ERROR/MainProcess] consumer: Cannot connect to redis://redis:6379/0: Error -2 connecting to redis:6379. Name does not resolve..
Trying again in 16.00 seconds... (8/100)

[2022-12-01 21:24:17,322: ERROR/MainProcess] consumer: Cannot connect to redis://redis:6379/0: Error -2 connecting to redis:6379. Name does not resolve..
Trying again in 18.00 seconds... (9/100)

[2022-12-01 21:24:35,410: ERROR/MainProcess] consumer: Cannot connect to redis://redis:6379/0: Error -2 connecting to redis:6379. Name does not resolve..
Trying again in 20.00 seconds... (10/100)

[2022-12-01 21:24:55,511: ERROR/MainProcess] consumer: Cannot connect to redis://redis:6379/0: Error -2 connecting to redis:6379. Name does not resolve..
Trying again in 22.00 seconds... (11/100)

[2022-12-01 21:25:17,610: ERROR/MainProcess] consumer: Cannot connect to redis://redis:6379/0: Error -2 connecting to redis:6379. Name does not resolve..
Trying again in 24.00 seconds... (12/100)

[2022-12-01 21:25:44,066: ERROR/MainProcess] consumer: Cannot connect to redis://redis:6379/0: Error -2 connecting to redis:6379. Name does not resolve..
Trying again in 26.00 seconds... (13/100)

[2022-12-01 21:26:11,129: ERROR/MainProcess] consumer: Cannot connect to redis://redis:6379/0: Error -2 connecting to redis:6379. Name does not resolve..
Trying again in 28.00 seconds... (14/100)

[2022-12-01 21:26:38,943: ERROR/MainProcess] consumer: Cannot connect to redis://redis:6379/0: Error -2 connecting to redis:6379. Name does not resolve..
Trying again in 30.00 seconds... (15/100)

[2022-12-01 23:26:35,585: ERROR/MainProcess] consumer: Cannot connect to redis://redis:6379/0: Error -2 connecting to redis:6379. Name does not resolve..
Trying again in 32.00 seconds... (16/100)

[2022-12-02 05:21:16,390: ERROR/MainProcess] consumer: Cannot connect to redis://redis:6379/0: Error -2 connecting to redis:6379. Name does not resolve..
Trying again in 32.00 seconds... (16/100)

[2022-12-02 05:21:48,807: ERROR/MainProcess] consumer: Cannot connect to redis://redis:6379/0: Error -2 connecting to redis:6379. Name does not resolve..
Trying again in 32.00 seconds... (16/100)

[2022-12-02 05:22:21,085: ERROR/MainProcess] consumer: Cannot connect to redis://redis:6379/0: Error -2 connecting to redis:6379. Name does not resolve..
Trying again in 32.00 seconds... (16/100)

[2022-12-02 05:22:53,456: ERROR/MainProcess] consumer: Cannot connect to redis://redis:6379/0: Error -2 connecting to redis:6379. Name does not resolve..
Trying again in 32.00 seconds... (16/100)

[2022-12-02 05:23:25,762: ERROR/MainProcess] consumer: Cannot connect to redis://redis:6379/0: Error -2 connecting to redis:6379. Name does not resolve..
Trying again in 32.00 seconds... (16/100)

[2022-12-02 05:23:58,060: ERROR/MainProcess] consumer: Cannot connect to redis://redis:6379/0: Error -2 connecting to redis:6379. Name does not resolve..
Trying again in 32.00 seconds... (16/100)

[2022-12-02 05:24:30,180: ERROR/MainProcess] consumer: Cannot connect to redis://redis:6379/0: Error -2 connecting to redis:6379. Name does not resolve..
Trying again in 32.00 seconds... (16/100)

[2022-12-02 05:25:02,271: ERROR/MainProcess] consumer: Cannot connect to redis://redis:6379/0: Error -2 connecting to redis:6379. Name does not resolve..
Trying again in 32.00 seconds... (16/100)

[2022-12-02 05:25:34,458: ERROR/MainProcess] consumer: Cannot connect to redis://redis:6379/0: Error -2 connecting to redis:6379. Name does not resolve..
Trying again in 32.00 seconds... (16/100)

[2022-12-02 05:26:06,604: ERROR/MainProcess] consumer: Cannot connect to redis://redis:6379/0: Error -2 connecting to redis:6379. Name does not resolve..
Trying again in 32.00 seconds... (16/100)

[2022-12-02 05:26:38,769: ERROR/MainProcess] consumer: Cannot connect to redis://redis:6379/0: Error -2 connecting to redis:6379. Name does not resolve..
Trying again in 32.00 seconds... (16/100)

[2022-12-02 05:27:10,920: ERROR/MainProcess] consumer: Cannot connect to redis://redis:6379/0: Error -2 connecting to redis:6379. Name does not resolve..
Trying again in 32.00 seconds... (16/100)

[2022-12-02 05:27:43,119: ERROR/MainProcess] consumer: Cannot connect to redis://redis:6379/0: Error -2 connecting to redis:6379. Name does not resolve..
Trying again in 32.00 seconds... (16/100)

[2022-12-02 05:28:15,226: ERROR/MainProcess] consumer: Cannot connect to redis://redis:6379/0: Error -2 connecting to redis:6379. Name does not resolve..
Trying again in 32.00 seconds... (16/100)

[2022-12-02 05:28:47,371: ERROR/MainProcess] consumer: Cannot connect to redis://redis:6379/0: Error -2 connecting to redis:6379. Name does not resolve..
Trying again in 32.00 seconds... (16/100)

[2022-12-02 05:29:19,459: ERROR/MainProcess] consumer: Cannot connect to redis://redis:6379/0: Error -2 connecting to redis:6379. Name does not resolve..
Trying again in 32.00 seconds... (16/100)

[2022-12-02 05:29:51,545: ERROR/MainProcess] consumer: Cannot connect to redis://redis:6379/0: Error -2 connecting to redis:6379. Name does not resolve..
Trying again in 32.00 seconds... (16/100)

[2022-12-02 05:30:23,679: ERROR/MainProcess] consumer: Cannot connect to redis://redis:6379/0: Error -2 connecting to redis:6379. Name does not resolve..
Trying again in 32.00 seconds... (16/100)

[2022-12-02 05:30:55,785: ERROR/MainProcess] consumer: Cannot connect to redis://redis:6379/0: Error -2 connecting to redis:6379. Name does not resolve..
Trying again in 32.00 seconds... (16/100)

[2022-12-02 05:31:27,891: ERROR/MainProcess] consumer: Cannot connect to redis://redis:6379/0: Error -2 connecting to redis:6379. Name does not resolve..
Trying again in 32.00 seconds... (16/100)

[2022-12-02 05:31:59,994: ERROR/MainProcess] consumer: Cannot connect to redis://redis:6379/0: Error -2 connecting to redis:6379. Name does not resolve..
Trying again in 32.00 seconds... (16/100)

[2022-12-02 05:32:32,087: ERROR/MainProcess] consumer: Cannot connect to redis://redis:6379/0: Error -2 connecting to redis:6379. Name does not resolve..
Trying again in 32.00 seconds... (16/100)

[2022-12-02 05:33:04,154: ERROR/MainProcess] consumer: Cannot connect to redis://redis:6379/0: Error -2 connecting to redis:6379. Name does not resolve..
Trying again in 32.00 seconds... (16/100)

[2022-12-02 05:33:36,245: ERROR/MainProcess] consumer: Cannot connect to redis://redis:6379/0: Error -2 connecting to redis:6379. Name does not resolve..
Trying again in 32.00 seconds... (16/100)

[2022-12-02 05:34:08,334: ERROR/MainProcess] consumer: Cannot connect to redis://redis:6379/0: Error -2 connecting to redis:6379. Name does not resolve..
Trying again in 32.00 seconds... (16/100)

[2022-12-02 05:34:40,412: ERROR/MainProcess] consumer: Cannot connect to redis://redis:6379/0: Error -2 connecting to redis:6379. Name does not resolve..
Trying again in 32.00 seconds... (16/100)

[2022-12-02 05:35:12,520: ERROR/MainProcess] consumer: Cannot connect to redis://redis:6379/0: Error -2 connecting to redis:6379. Name does not resolve..
Trying again in 32.00 seconds... (16/100)

[2022-12-02 05:35:44,589: ERROR/MainProcess] consumer: Cannot connect to redis://redis:6379/0: Error -2 connecting to redis:6379. Name does not resolve..
Trying again in 32.00 seconds... (16/100)

[2022-12-02 05:36:16,608: ERROR/MainProcess] consumer: Cannot connect to redis://redis:6379/0: Error -2 connecting to redis:6379. Name does not resolve..
Trying again in 32.00 seconds... (16/100)

[2022-12-02 05:36:48,709: ERROR/MainProcess] consumer: Cannot connect to redis://redis:6379/0: Error -2 connecting to redis:6379. Name does not resolve..
Trying again in 32.00 seconds... (16/100)

[2022-12-02 05:37:20,776: ERROR/MainProcess] consumer: Cannot connect to redis://redis:6379/0: Error -2 connecting to redis:6379. Name does not resolve..
Trying again in 32.00 seconds... (16/100)

[2022-12-02 05:37:52,870: ERROR/MainProcess] consumer: Cannot connect to redis://redis:6379/0: Error -2 connecting to redis:6379. Name does not resolve..
Trying again in 32.00 seconds... (16/100)

[2022-12-02 05:38:24,968: ERROR/MainProcess] consumer: Cannot connect to redis://redis:6379/0: Error -2 connecting to redis:6379. Name does not resolve..
Trying again in 32.00 seconds... (16/100)

[2022-12-02 05:38:57,137: ERROR/MainProcess] consumer: Cannot connect to redis://redis:6379/0: Error -2 connecting to redis:6379. Name does not resolve..
Trying again in 32.00 seconds... (16/100)

[2022-12-02 05:39:29,241: ERROR/MainProcess] consumer: Cannot connect to redis://redis:6379/0: Error -2 connecting to redis:6379. Name does not resolve..
Trying again in 32.00 seconds... (16/100)

[2022-12-02 05:40:01,312: ERROR/MainProcess] consumer: Cannot connect to redis://redis:6379/0: Error -2 connecting to redis:6379. Name does not resolve..
Trying again in 32.00 seconds... (16/100)

[2022-12-02 05:40:33,378: ERROR/MainProcess] consumer: Cannot connect to redis://redis:6379/0: Error -2 connecting to redis:6379. Name does not resolve..
Trying again in 32.00 seconds... (16/100)

[2022-12-02 05:41:05,454: ERROR/MainProcess] consumer: Cannot connect to redis://redis:6379/0: Error -2 connecting to redis:6379. Name does not resolve..
Trying again in 32.00 seconds... (16/100)

[2022-12-02 05:41:37,546: ERROR/MainProcess] consumer: Cannot connect to redis://redis:6379/0: Error -2 connecting to redis:6379. Name does not resolve..
Trying again in 32.00 seconds... (16/100)

[2022-12-02 05:42:09,619: ERROR/MainProcess] consumer: Cannot connect to redis://redis:6379/0: Error -2 connecting to redis:6379. Name does not resolve..
Trying again in 32.00 seconds... (16/100)

[2022-12-02 05:42:41,693: ERROR/MainProcess] consumer: Cannot connect to redis://redis:6379/0: Error -2 connecting to redis:6379. Name does not resolve..
Trying again in 32.00 seconds... (16/100)

[2022-12-02 05:43:13,775: ERROR/MainProcess] consumer: Cannot connect to redis://redis:6379/0: Error -2 connecting to redis:6379. Name does not resolve..
Trying again in 32.00 seconds... (16/100)

[2022-12-02 05:43:45,840: ERROR/MainProcess] consumer: Cannot connect to redis://redis:6379/0: Error -2 connecting to redis:6379. Name does not resolve..
Trying again in 32.00 seconds... (16/100)

[2022-12-02 05:44:17,944: ERROR/MainProcess] consumer: Cannot connect to redis://redis:6379/0: Error -2 connecting to redis:6379. Name does not resolve..
Trying again in 32.00 seconds... (16/100)

[2022-12-02 05:44:50,016: ERROR/MainProcess] consumer: Cannot connect to redis://redis:6379/0: Error -2 connecting to redis:6379. Name does not resolve..
Trying again in 32.00 seconds... (16/100)

[2022-12-02 05:45:22,099: ERROR/MainProcess] consumer: Cannot connect to redis://redis:6379/0: Error -2 connecting to redis:6379. Name does not resolve..
Trying again in 32.00 seconds... (16/100)

[2022-12-02 05:45:54,166: ERROR/MainProcess] consumer: Cannot connect to redis://redis:6379/0: Error -2 connecting to redis:6379. Name does not resolve..
Trying again in 32.00 seconds... (16/100)

[2022-12-02 05:46:26,272: ERROR/MainProcess] consumer: Cannot connect to redis://redis:6379/0: Error -2 connecting to redis:6379. Name does not resolve..
Trying again in 32.00 seconds... (16/100)

[2022-12-02 05:46:58,377: ERROR/MainProcess] consumer: Cannot connect to redis://redis:6379/0: Error -2 connecting to redis:6379. Name does not resolve..
Trying again in 32.00 seconds... (16/100)

[2022-12-02 05:47:30,450: ERROR/MainProcess] consumer: Cannot connect to redis://redis:6379/0: Error -2 connecting to redis:6379. Name does not resolve..
Trying again in 32.00 seconds... (16/100)

[2022-12-02 05:48:02,538: ERROR/MainProcess] consumer: Cannot connect to redis://redis:6379/0: Error -2 connecting to redis:6379. Name does not resolve..
Trying again in 32.00 seconds... (16/100)

[2022-12-02 05:48:34,616: ERROR/MainProcess] consumer: Cannot connect to redis://redis:6379/0: Error -2 connecting to redis:6379. Name does not resolve..
Trying again in 32.00 seconds... (16/100)

[2022-12-02 05:49:06,685: ERROR/MainProcess] consumer: Cannot connect to redis://redis:6379/0: Error -2 connecting to redis:6379. Name does not resolve..
Trying again in 32.00 seconds... (16/100)

[2022-12-02 05:49:38,753: ERROR/MainProcess] consumer: Cannot connect to redis://redis:6379/0: Error -2 connecting to redis:6379. Name does not resolve..
Trying again in 32.00 seconds... (16/100)

[2022-12-02 05:50:10,843: ERROR/MainProcess] consumer: Cannot connect to redis://redis:6379/0: Error -2 connecting to redis:6379. Name does not resolve..
Trying again in 32.00 seconds... (16/100)

[2022-12-02 05:50:42,985: ERROR/MainProcess] consumer: Cannot connect to redis://redis:6379/0: Error -2 connecting to redis:6379. Name does not resolve..
Trying again in 32.00 seconds... (16/100)

[2022-12-02 05:51:15,136: ERROR/MainProcess] consumer: Cannot connect to redis://redis:6379/0: Error -2 connecting to redis:6379. Name does not resolve..
Trying again in 32.00 seconds... (16/100)

[2022-12-02 05:51:47,274: ERROR/MainProcess] consumer: Cannot connect to redis://redis:6379/0: Error -2 connecting to redis:6379. Name does not resolve..
Trying again in 32.00 seconds... (16/100)

[2022-12-02 05:52:19,336: ERROR/MainProcess] consumer: Cannot connect to redis://redis:6379/0: Error -2 connecting to redis:6379. Name does not resolve..
Trying again in 32.00 seconds... (16/100)

[2022-12-02 05:52:51,421: ERROR/MainProcess] consumer: Cannot connect to redis://redis:6379/0: Error -2 connecting to redis:6379. Name does not resolve..
Trying again in 32.00 seconds... (16/100)

[2022-12-02 05:53:26,219: ERROR/MainProcess] consumer: Cannot connect to redis://redis:6379/0: Error -2 connecting to redis:6379. Name does not resolve..
Trying again in 32.00 seconds... (16/100)

[2022-12-02 05:53:58,920: ERROR/MainProcess] consumer: Cannot connect to redis://redis:6379/0: Error -2 connecting to redis:6379. Name does not resolve..
Trying again in 32.00 seconds... (16/100)

[2022-12-02 05:54:31,237: ERROR/MainProcess] consumer: Cannot connect to redis://redis:6379/0: Error -2 connecting to redis:6379. Name does not resolve..
Trying again in 32.00 seconds... (16/100)

[2022-12-02 05:55:03,540: ERROR/MainProcess] consumer: Cannot connect to redis://redis:6379/0: Error -2 connecting to redis:6379. Name does not resolve..
Trying again in 32.00 seconds... (16/100)

[2022-12-02 05:55:35,647: ERROR/MainProcess] consumer: Cannot connect to redis://redis:6379/0: Error -2 connecting to redis:6379. Name does not resolve..
Trying again in 32.00 seconds... (16/100)

[2022-12-02 05:56:07,833: ERROR/MainProcess] consumer: Cannot connect to redis://redis:6379/0: Error -2 connecting to redis:6379. Name does not resolve..
Trying again in 32.00 seconds... (16/100)

[2022-12-02 05:56:40,042: ERROR/MainProcess] consumer: Cannot connect to redis://redis:6379/0: Error -2 connecting to redis:6379. Name does not resolve..
Trying again in 32.00 seconds... (16/100)

[2022-12-02 05:57:12,495: ERROR/MainProcess] consumer: Cannot connect to redis://redis:6379/0: Error -2 connecting to redis:6379. Name does not resolve..
Trying again in 32.00 seconds... (16/100)

[2022-12-02 05:57:44,762: ERROR/MainProcess] consumer: Cannot connect to redis://redis:6379/0: Error -2 connecting to redis:6379. Name does not resolve..
Trying again in 32.00 seconds... (16/100)

[2022-12-02 05:58:17,046: ERROR/MainProcess] consumer: Cannot connect to redis://redis:6379/0: Error -2 connecting to redis:6379. Name does not resolve..
Trying again in 32.00 seconds... (16/100)

[2022-12-02 05:58:49,791: ERROR/MainProcess] consumer: Cannot connect to redis://redis:6379/0: Error -2 connecting to redis:6379. Name does not resolve..
Trying again in 32.00 seconds... (16/100)

[2022-12-02 05:59:22,441: ERROR/MainProcess] consumer: Cannot connect to redis://redis:6379/0: Error -2 connecting to redis:6379. Name does not resolve..
Trying again in 32.00 seconds... (16/100)

[2022-12-02 05:59:54,712: ERROR/MainProcess] consumer: Cannot connect to redis://redis:6379/0: Error -2 connecting to redis:6379. Name does not resolve..
Trying again in 32.00 seconds... (16/100)

[2022-12-02 06:00:26,816: ERROR/MainProcess] consumer: Cannot connect to redis://redis:6379/0: Error -2 connecting to redis:6379. Name does not resolve..
Trying again in 32.00 seconds... (16/100)

[2022-12-02 06:00:58,909: ERROR/MainProcess] consumer: Cannot connect to redis://redis:6379/0: Error -2 connecting to redis:6379. Name does not resolve..
Trying again in 32.00 seconds... (16/100)

[2022-12-02 06:01:31,048: ERROR/MainProcess] consumer: Cannot connect to redis://redis:6379/0: Error -2 connecting to redis:6379. Name does not resolve..
Trying again in 32.00 seconds... (16/100)

[2022-12-02 06:02:03,248: ERROR/MainProcess] consumer: Cannot connect to redis://redis:6379/0: Error -2 connecting to redis:6379. Name does not resolve..
Trying again in 32.00 seconds... (16/100)

[2022-12-02 06:02:35,398: ERROR/MainProcess] consumer: Cannot connect to redis://redis:6379/0: Error -2 connecting to redis:6379. Name does not resolve..
Trying again in 32.00 seconds... (16/100)

[2022-12-02 06:03:07,576: ERROR/MainProcess] consumer: Cannot connect to redis://redis:6379/0: Error -2 connecting to redis:6379. Name does not resolve..
Trying again in 32.00 seconds... (16/100)

[2022-12-02 06:03:39,987: ERROR/MainProcess] consumer: Cannot connect to redis://redis:6379/0: Error -2 connecting to redis:6379. Name does not resolve..
Trying again in 32.00 seconds... (16/100)

[2022-12-02 06:04:12,883: ERROR/MainProcess] consumer: Cannot connect to redis://redis:6379/0: Error -2 connecting to redis:6379. Name does not resolve..
Trying again in 32.00 seconds... (16/100)

[2022-12-02 06:04:45,726: ERROR/MainProcess] consumer: Cannot connect to redis://redis:6379/0: Error -2 connecting to redis:6379. Name does not resolve..
Trying again in 32.00 seconds... (16/100)

[2022-12-02 06:05:18,840: ERROR/MainProcess] consumer: Cannot connect to redis://redis:6379/0: Error -2 connecting to redis:6379. Name does not resolve..
Trying again in 32.00 seconds... (16/100)

[2022-12-02 06:05:51,909: ERROR/MainProcess] consumer: Cannot connect to redis://redis:6379/0: Error -2 connecting to redis:6379. Name does not resolve..
Trying again in 32.00 seconds... (16/100)

[2022-12-02 06:06:24,610: CRITICAL/MainProcess] Unrecoverable error: OperationalError('Error -2 connecting to redis:6379. Name does not resolve.')
Traceback (most recent call last):
  File "/usr/local/lib/python3.9/site-packages/kombu/transport/virtual/base.py", line 925, in create_channel
    return self._avail_channels.pop()
IndexError: pop from empty list

During handling of the above exception, another exception occurred:

Traceback (most recent call last):
  File "/usr/local/lib/python3.9/site-packages/redis/connection.py", line 611, in connect
    sock = self.retry.call_with_retry(
  File "/usr/local/lib/python3.9/site-packages/redis/retry.py", line 46, in call_with_retry
    return do()
  File "/usr/local/lib/python3.9/site-packages/redis/connection.py", line 612, in <lambda>
    lambda: self._connect(), lambda error: self.disconnect(error)
  File "/usr/local/lib/python3.9/site-packages/redis/connection.py", line 645, in _connect
    for res in socket.getaddrinfo(
  File "/usr/local/lib/python3.9/socket.py", line 953, in getaddrinfo
    for res in _socket.getaddrinfo(host, port, family, type, proto, flags):
socket.gaierror: [Errno -2] Name does not resolve

During handling of the above exception, another exception occurred:

Traceback (most recent call last):
  File "/usr/local/lib/python3.9/site-packages/kombu/connection.py", line 446, in _reraise_as_library_errors
    yield
  File "/usr/local/lib/python3.9/site-packages/kombu/connection.py", line 433, in _ensure_connection
    return retry_over_time(
  File "/usr/local/lib/python3.9/site-packages/kombu/utils/functional.py", line 312, in retry_over_time
    return fun(*args, **kwargs)
  File "/usr/local/lib/python3.9/site-packages/kombu/connection.py", line 877, in _connection_factory
    self._connection = self._establish_connection()
  File "/usr/local/lib/python3.9/site-packages/kombu/connection.py", line 812, in _establish_connection
    conn = self.transport.establish_connection()
  File "/usr/local/lib/python3.9/site-packages/kombu/transport/virtual/base.py", line 949, in establish_connection
    self._avail_channels.append(self.create_channel(self))
  File "/usr/local/lib/python3.9/site-packages/kombu/transport/virtual/base.py", line 927, in create_channel
    channel = self.Channel(connection)
  File "/usr/local/lib/python3.9/site-packages/kombu/transport/redis.py", line 737, in __init__
    self.client.ping()
  File "/usr/local/lib/python3.9/site-packages/redis/commands/core.py", line 1132, in ping
    return self.execute_command("PING", **kwargs)
  File "/usr/local/lib/python3.9/site-packages/redis/client.py", line 1235, in execute_command
    conn = self.connection or pool.get_connection(command_name, **options)
  File "/usr/local/lib/python3.9/site-packages/redis/connection.py", line 1387, in get_connection
    connection.connect()
  File "/usr/local/lib/python3.9/site-packages/redis/connection.py", line 617, in connect
    raise ConnectionError(self._error_message(e))
redis.exceptions.ConnectionError: Error -2 connecting to redis:6379. Name does not resolve.

The above exception was the direct cause of the following exception:

Traceback (most recent call last):
  File "/usr/local/lib/python3.9/site-packages/celery/worker/worker.py", line 203, in start
    self.blueprint.start(self)
  File "/usr/local/lib/python3.9/site-packages/celery/bootsteps.py", line 116, in start
    step.start(parent)
  File "/usr/local/lib/python3.9/site-packages/celery/bootsteps.py", line 365, in start
    return self.obj.start()
  File "/usr/local/lib/python3.9/site-packages/celery/worker/consumer/consumer.py", line 332, in start
    blueprint.start(self)
  File "/usr/local/lib/python3.9/site-packages/celery/bootsteps.py", line 116, in start
    step.start(parent)
  File "/usr/local/lib/python3.9/site-packages/celery/worker/consumer/connection.py", line 21, in start
    c.connection = c.connect()
  File "/usr/local/lib/python3.9/site-packages/celery/worker/consumer/consumer.py", line 428, in connect
    conn = self.connection_for_read(heartbeat=self.amqheartbeat)
  File "/usr/local/lib/python3.9/site-packages/celery/worker/consumer/consumer.py", line 434, in connection_for_read
    return self.ensure_connected(
  File "/usr/local/lib/python3.9/site-packages/celery/worker/consumer/consumer.py", line 460, in ensure_connected
    conn = conn.ensure_connection(
  File "/usr/local/lib/python3.9/site-packages/kombu/connection.py", line 381, in ensure_connection
    self._ensure_connection(*args, **kwargs)
  File "/usr/local/lib/python3.9/site-packages/kombu/connection.py", line 433, in _ensure_connection
    return retry_over_time(
  File "/usr/local/lib/python3.9/contextlib.py", line 135, in __exit__
    self.gen.throw(type, value, traceback)
  File "/usr/local/lib/python3.9/site-packages/kombu/connection.py", line 450, in _reraise_as_library_errors
    raise ConnectionError(str(exc)) from exc
kombu.exceptions.OperationalError: Error -2 connecting to redis:6379. Name does not resolve.
[2022-12-02 06:07:32,401: ERROR/MainProcess] consumer: Cannot connect to redis://redis:6379/0: Error -2 connecting to redis:6379. Name does not resolve..
Trying again in 2.00 seconds... (1/100)

[2022-12-02 06:07:34,585: ERROR/MainProcess] consumer: Cannot connect to redis://redis:6379/0: Error -2 connecting to redis:6379. Name does not resolve..
Trying again in 4.00 seconds... (2/100)

[2022-12-02 06:07:38,714: ERROR/MainProcess] consumer: Cannot connect to redis://redis:6379/0: Error -2 connecting to redis:6379. Name does not resolve..
Trying again in 6.00 seconds... (3/100)

[2022-12-02 06:07:44,809: ERROR/MainProcess] consumer: Cannot connect to redis://redis:6379/0: Error -2 connecting to redis:6379. Name does not resolve..
Trying again in 8.00 seconds... (4/100)

[2022-12-02 06:07:53,470: ERROR/MainProcess] consumer: Cannot connect to redis://redis:6379/0: Error -2 connecting to redis:6379. Name does not resolve..
Trying again in 10.00 seconds... (5/100)

[2022-12-02 06:08:04,530: ERROR/MainProcess] consumer: Cannot connect to redis://redis:6379/0: Error -2 connecting to redis:6379. Name does not resolve..
Trying again in 12.00 seconds... (6/100)

[2022-12-02 06:08:17,761: ERROR/MainProcess] consumer: Cannot connect to redis://redis:6379/0: Error -2 connecting to redis:6379. Name does not resolve..
Trying again in 14.00 seconds... (7/100)

[2022-12-02 06:08:33,612: ERROR/MainProcess] consumer: Cannot connect to redis://redis:6379/0: Error -2 connecting to redis:6379. Name does not resolve..
Trying again in 16.00 seconds... (8/100)

[2022-12-02 06:08:51,872: ERROR/MainProcess] consumer: Cannot connect to redis://redis:6379/0: Error -2 connecting to redis:6379. Name does not resolve..
Trying again in 18.00 seconds... (9/100)

[2022-12-02 06:09:13,401: ERROR/MainProcess] consumer: Cannot connect to redis://redis:6379/0: Error -2 connecting to redis:6379. Name does not resolve..
Trying again in 20.00 seconds... (10/100)

[2022-12-02 06:09:36,108: ERROR/MainProcess] consumer: Cannot connect to redis://redis:6379/0: Error -2 connecting to redis:6379. Name does not resolve..
Trying again in 22.00 seconds... (11/100)

[2022-12-02 06:09:59,843: ERROR/MainProcess] consumer: Cannot connect to redis://redis:6379/0: Error -2 connecting to redis:6379. Name does not resolve..
Trying again in 24.00 seconds... (12/100)

[2022-12-02 06:10:24,363: ERROR/MainProcess] consumer: Cannot connect to redis://redis:6379/0: Error -2 connecting to redis:6379. Name does not resolve..
Trying again in 26.00 seconds... (13/100)

[2022-12-02 06:10:51,994: ERROR/MainProcess] consumer: Cannot connect to redis://redis:6379/0: Error -2 connecting to redis:6379. Name does not resolve..
Trying again in 28.00 seconds... (14/100)

[2022-12-02 06:11:20,736: ERROR/MainProcess] consumer: Cannot connect to redis://redis:6379/0: Error -2 connecting to redis:6379. Name does not resolve..
Trying again in 30.00 seconds... (15/100)

[2022-12-02 06:11:52,843: ERROR/MainProcess] consumer: Cannot connect to redis://redis:6379/0: Error -2 connecting to redis:6379. Name does not resolve..
Trying again in 32.00 seconds... (16/100)

[2022-12-02 06:12:26,291: ERROR/MainProcess] consumer: Cannot connect to redis://redis:6379/0: Error -2 connecting to redis:6379. Name does not resolve..
Trying again in 32.00 seconds... (16/100)

[2022-12-02 06:13:03,597: ERROR/MainProcess] consumer: Cannot connect to redis://redis:6379/0: Error 111 connecting to redis:6379. Connection refused..
Trying again in 32.00 seconds... (16/100)

[2022-12-02 06:13:41,876: INFO/MainProcess] Connected to redis://redis:6379/0
[2022-12-02 06:13:43,538: INFO/MainProcess] mingle: searching for neighbors
[2022-12-02 06:13:48,088: INFO/MainProcess] mingle: all alone
[2022-12-02 06:13:50,789: WARNING/MainProcess] /usr/local/lib/python3.9/site-packages/celery/fixups/django.py:203: UserWarning: Using settings.DEBUG leads to a memory
            leak, never use this setting in production environments!
  warnings.warn('''Using settings.DEBUG leads to a memory

[2022-12-02 06:13:51,556: INFO/MainProcess] celery@34c82f12f97e ready.
[2022-12-02 06:16:26,212: INFO/MainProcess] Events of group {task} enabled by remote.
[2022-12-02 06:24:24,594: INFO/MainProcess] Connected to redis://redis:6379/0
[2022-12-02 06:24:27,188: INFO/MainProcess] mingle: searching for neighbors
[2022-12-02 06:24:32,410: INFO/MainProcess] mingle: all alone
[2022-12-02 06:24:36,570: WARNING/MainProcess] /usr/local/lib/python3.9/site-packages/celery/fixups/django.py:203: UserWarning: Using settings.DEBUG leads to a memory
            leak, never use this setting in production environments!
  warnings.warn('''Using settings.DEBUG leads to a memory

[2022-12-02 06:24:38,538: INFO/MainProcess] celery@34c82f12f97e ready.
[2022-12-02 06:26:21,425: INFO/MainProcess] Events of group {task} enabled by remote.
[2022-12-02 06:47:16,813: INFO/MainProcess] Connected to redis://redis:6379/0
[2022-12-02 06:47:19,889: INFO/MainProcess] mingle: searching for neighbors
[2022-12-02 06:47:22,070: INFO/MainProcess] mingle: all alone
[2022-12-02 06:47:23,348: WARNING/MainProcess] /usr/local/lib/python3.9/site-packages/celery/fixups/django.py:203: UserWarning: Using settings.DEBUG leads to a memory
            leak, never use this setting in production environments!
  warnings.warn('''Using settings.DEBUG leads to a memory

[2022-12-02 06:47:23,451: INFO/MainProcess] celery@34c82f12f97e ready.
[2022-12-02 06:47:47,605: INFO/MainProcess] Events of group {task} enabled by remote.
[2022-12-02 07:01:26,377: INFO/MainProcess] Connected to redis://redis:6379/0
[2022-12-02 07:01:27,170: INFO/MainProcess] mingle: searching for neighbors
[2022-12-02 07:01:30,597: INFO/MainProcess] mingle: all alone
[2022-12-02 07:01:36,476: WARNING/MainProcess] /usr/local/lib/python3.9/site-packages/celery/fixups/django.py:203: UserWarning: Using settings.DEBUG leads to a memory
            leak, never use this setting in production environments!
  warnings.warn('''Using settings.DEBUG leads to a memory

[2022-12-02 07:01:36,712: INFO/MainProcess] celery@34c82f12f97e ready.
[2022-12-02 07:01:37,328: INFO/MainProcess] Task feedback.tasks.send_feedback_email_task[bf32004f-06ae-42fa-b3a2-0fd110d0107a] received
[2022-12-02 07:02:01,104: WARNING/ForkPoolWorker-1] Content-Type: text/plain; charset="utf-8"
MIME-Version: 1.0
Content-Transfer-Encoding: 7bit
Subject: Your Feedback
From: support@example.com
To: josefkariuki@gmail.com
Date: Fri, 02 Dec 2022 07:02:01 -0000
Message-ID: <166996452106.8.11931782509270198842@34c82f12f97e>

	testing

Thank you!
[2022-12-02 07:02:03,067: WARNING/ForkPoolWorker-1] -------------------------------------------------------------------------------
[2022-12-02 07:02:03,594: INFO/MainProcess] Events of group {task} enabled by remote.
[2022-12-02 07:02:06,075: INFO/ForkPoolWorker-1] Task feedback.tasks.send_feedback_email_task[bf32004f-06ae-42fa-b3a2-0fd110d0107a] succeeded in 27.98950770999727s: None
